Workbook

Sheet Data
A1: Order ID | B1: Date | C1: Product | D1: Category | E1: Region | F1: Quantity | G1: Sales | H1: Profit
A2: ORD0001 | B2: 45798 | C2: 24 inch Monitor | D2: Electronics | E2: South | F2: 1 | G2: 170.04 | H2: 38.65
A3: ORD0002 | B3: 45960 | C3: Webcam | D3: Electronics | E3: West | F3: 2 | G3: 135.95 | H3: 13.42
A4: ORD0003 | B4: 45945 | C4: Keyboard | D4: Accessories | E4: South | F4: 1 | G4: 41.73 | H4: 9.19
A5: ORD0004 | B5: 45887 | C5: Desk | D5: Furniture | E5: East | F5: 4 | G5: 1274.26 | H5: 103.6
A6: ORD0005 | B6: 45832 | C6: Wireless Mouse | D6: Accessories | E6: East | F6: 7 | G6: 162.94 | H6: 44.23
A7: ORD0006 | B7: 45705 | C7: Office Chair | D7: Furniture | E7: West | F7: 2 | G7: 404.51 | H7: 100.92
A8: ORD0007 | B8: 45680 | C8: USB Hub | D8: Accessories | E8: West | F8: 5 | G8: 151.09 | H8: 41.49
A9: ORD0008 | B9: 45940 | C9: Desk | D9: Furniture | E9: East | F9: 2 | G9: 639.53 | H9: 130.27
A10: ORD0009 | B10: 46018 | C10: Office Chair | D10: Furniture | E10: North | F10: 4 | G10: 800.07 | H10: 100.47
A11: ORD0010 | B11: 45777 | C11: Headphones | D11: Accessories | E11: North | F11: 2 | G11: 117.12 | H11: 19.99
A12: ORD0011 | B12: 45847 | C12: Office Chair | D12: Furniture | E12: East | F12: 3 | G12: 621.65 | H12: 82.93
A13: ORD0012 | B13: 45931 | C13: 24 inch Monitor | D13: Electronics | E13: South | F13: 3 | G13: 503.65 | H13: 78.51
... A501: ORD0500 | B501: 45772 | C501: Laptop | D501: Electronics | E501: North | F501: 3 | G501: 2127.09 | H501: 199.49

Sheet Analysis
A1: Table 1 Overall KPIs
A2: Total Orders | B2: =COUNTA(Data!A:A)-1 -> 500
A3: Total Quantity Sold | B3: =SUM(Data!F:F) -> 2274
A4: Total Sales | B4: =SUM(Data!G:G) -> 374771.8
A5: Total Profit | B5: =SUM(Data!H:H) -> 68007.34
A7: Table 2 Sales by Product
A8: Product | B8: Total Quantity | C8: Total Sales | D8: Total Profit
A9: Laptop | B9: =SUMIF(Data!C:C,A9,Data!F:F) -> 198 | C9: =SUMIF(Data!C:C,A9,Data!G:G) -> 129730.52 | D9: =SUMIF(Data!C:C,A9,Data!H:H) -> 23617
A10: 24 inch Monitor | B10: =SUMIF(Data!C:C,A10,Data!F:F) -> 229 | C10: =SUMIF(Data!C:C,A10,Data!G:G) -> 40957 | D10: =SUMIF(Data!C:C,A10,Data!H:H) -> 7929.67
A11: Wireless Mouse | B11: =SUMIF(Data!C:C,A11,Data!F:F) -> 261 | C11: =SUMIF(Data!C:C,A11,Data!G:G) -> 6595.28 | D11: =SUMIF(Data!C:C,A11,Data!H:H) -> 1171.6
A12: Keyboard | B12: =SUMIF(Data!C:C,A12,Data!F:F) -> 202 | C12: =SUMIF(Data!C:C,A12,Data!G:G) -> 7970.66 | D12: =SUMIF(Data!C:C,A12,Data!H:H) -> 1597.52
A13: Headphones | B13: =SUMIF(Data!C:C,A13,Data!F:F) -> 244 | C13: =SUMIF(Data!C:C,A13,Data!G:G) -> 14798.38 | D13: =SUMIF(Data!C:C,A13,Data!H:H) -> 2560.12
A14: Office Chair | B14: =SUMIF(Data!C:C,A14,Data!F:F) -> 232 | C14: =SUMIF(Data!C:C,A14,Data!G:G) -> 51194.25 | D14: =SUMIF(Data!C:C,A14,Data!H:H) -> 9656.49
A15: Desk | B15: =SUMIF(Data!C:C,A15,Data!F:F) -> 209 | C15: =SUMIF(Data!C:C,A15,Data!G:G) -> 62800.05 | D15: =SUMIF(Data!C:C,A15,Data!H:H) -> 10656.55
A16: Printer | B16: =SUMIF(Data!C:C,A16,Data!F:F) -> 227 | C16: =SUMIF(Data!C:C,A16,Data!G:G) -> 36156.89 | D16: =SUMIF(Data!C:C,A16,Data!H:H) -> 6497.38
A17: Webcam | B17: =SUMIF(Data!C:C,A17,Data!F:F) -> 228 | C17: =SUMIF(Data!C:C,A17,Data!G:G) -> 17155.04 | D17: =SUMIF(Data!C:C,A17,Data!H:H) -> 2954.85
A18: USB Hub | B18: =SUMIF(Data!C:C,A18,Data!F:F) -> 244 | C18: =SUMIF(Data!C:C,A18,Data!G:G) -> 7413.73 | D18: =SUMIF(Data!C:C,A18,Data!H:H) -> 1366.16
A20: Table 3 Sales by Region
A21: Region | B21: Total Orders | C21: Total Sales | D21: Total Profit
A22: North | B22: =COUNTIF(Data!E:E,A22) -> 137 | C22: =SUMIF(Data!E:E,A22,Data!G:G) -> 113374.47 | D22: =SUMIF(Data!E:E,A22,Data!H:H) -> 20194.51
A23: South | B23: =COUNTIF(Data!E:E,A23) -> 114 | C23: =SUMIF(Data!E:E,A23,Data!G:G) -> 85396.84 | D23: =SUMIF(Data!E:E,A23,Data!H:H) -> 15727.34
A24: East | B24: =COUNTIF(Data!E:E,A24) -> 119 | C24: =SUMIF(Data!E:E,A24,Data!G:G) -> 94036.48 | D24: =SUMIF(Data!E:E,A24,Data!H:H) -> 17483.34
A25: West | B25: =COUNTIF(Data!E:E,A25) -> 130 | C25: =SUMIF(Data!E:E,A25,Data!G:G) -> 81964.01 | D25: =SUMIF(Data!E:E,A25,Data!H:H) -> 14602.15
A27: Table 4 Sales by Category
A28: Category | B28: Total Orders | C28: Total Sales | D28: Total Profit
A29: Electronics | B29: =COUNTIF(Data!D:D,A29) -> 197 | C29: =SUMIF(Data!D:D,A29,Data!G:G) -> 223999.45 | D29: =SUMIF(Data!D:D,A29,Data!H:H) -> 40998.9
A30: Accessories | B30: =COUNTIF(Data!D:D,A30) -> 205 | C30: =SUMIF(Data!D:D,A30,Data!G:G) -> 36778.05 | D30: =SUMIF(Data!D:D,A30,Data!H:H) -> 6695.4
A31: Furniture | B31: =COUNTIF(Data!D:D,A31) -> 98 | C31: =SUMIF(Data!D:D,A31,Data!G:G) -> 113994.3 | D31: =SUMIF(Data!D:D,A31,Data!H:H) -> 20313.04
A33: Table 5 Monthly Sales
A34: Month | B34: Total Sales | C34: Total Profit
A35: January | B35: {=SUMPRODUCT((MONTH(Data!$B$2:$B$501)=ROW()-34)*Data!$G$2:$G$501)} -> 24899.8 | C35: {=SUMPRODUCT((MONTH(Data!$B$2:$B$501)=ROW()-34)*Data!$H$2:$H$501)} -> 4501.78
A36: February | B36: {=SUMPRODUCT((MONTH(Data!$B$2:$B$501)=ROW()-34)*Data!$G$2:$G$501)} -> 30153.03 | C36: {=SUMPRODUCT((MONTH(Data!$B$2:$B$501)=ROW()-34)*Data!$H$2:$H$501)} -> 5316.82
A37: March | B37: {=SUMPRODUCT((MONTH(Data!$B$2:$B$501)=ROW()-34)*Data!$G$2:$G$501)} -> 19529.99 | C37: {=SUMPRODUCT((MONTH(Data!$B$2:$B$501)=ROW()-34)*Data!$H$2:$H$501)} -> 4029.56
A38: April | B38: {=SUMPRODUCT((MONTH(Data!$B$2:$B$501)=ROW()-34)*Data!$G$2:$G$501)} -> 40479.13 | C38: {=SUMPRODUCT((MONTH(Data!$B$2:$B$501)=ROW()-34)*Data!$H$2:$H$501)} -> 7218.49
A39: May | B39: {=SUMPRODUCT((MONTH(Data!$B$2:$B$501)=ROW()-34)*Data!$G$2:$G$501)} -> 41506.31 | C39: {=SUMPRODUCT((MONTH(Data!$B$2:$B$501)=ROW()-34)*Data!$H$2:$H$501)} -> 7871.75
A40: June | B40: {=SUMPRODUCT((MONTH(Data!$B$2:$B$501)=ROW()-34)*Data!$G$2:$G$501)} -> 39508.09 | C40: {=SUMPRODUCT((MONTH(Data!$B$2:$B$501)=ROW()-34)*Data!$H$2:$H$501)} -> 6910.24
A41: July | B41: {=SUMPRODUCT((MONTH(Data!$B$2:$B$501)=ROW()-34)*Data!$G$2:$G$501)} -> 25939.47 | C41: {=SUMPRODUCT((MONTH(Data!$B$2:$B$501)=ROW()-34)*Data!$H$2:$H$501)} -> 5336.61
A42: August | B42: {=SUMPRODUCT((MONTH(Data!$B$2:$B$501)=ROW()-34)*Data!$G$2:$G$501)} -> 23560.22 | C42: {=SUMPRODUCT((MONTH(Data!$B$2:$B$501)=ROW()-34)*Data!$H$2:$H$501)} -> 3876.78
A43: September | B43: {=SUMPRODUCT((MONTH(Data!$B$2:$B$501)=ROW()-34)*Data!$G$2:$G$501)} -> 34100.97 | C43: {=SUMPRODUCT((MONTH(Data!$B$2:$B$501)=ROW()-34)*Data!$H$2:$H$501)} -> 6477
A44: October | B44: {=SUMPRODUCT((MONTH(Data!$B$2:$B$501)=ROW()-34)*Data!$G$2:$G$501)} -> 20621.77 | C44: {=SUMPRODUCT((MONTH(Data!$B$2:$B$501)=ROW()-34)*Data!$H$2:$H$501)} -> 3585.24
...

Sheet Pivot_Product
A1: Sales & Profit by Product
A3: Row Labels | B3: Sum of Sales | C3: Sum of Profit
A4: 24 inch Monitor | B4: 40957 | C4: 7929.67
A5: Desk | B5: 62800.05 | C5: 10656.55
A6: Headphones | B6: 14798.38 | C6: 2560.12
A7: Keyboard | B7: 7970.66 | C7: 1597.52
A8: Laptop | B8: 129730.52 | C8: 23617
A9: Office Chair | B9: 51194.25 | C9: 9656.49
A10: Printer | B10: 36156.89 | C10: 6497.38
A11: USB Hub | B11: 7413.73 | C11: 1366.16
A12: Webcam | B12: 17155.04 | C12: 2954.85
A13: Wireless Mouse | B13: 6595.28 | C13: 1171.6
A14: Grand Total | B14: 374771.8 | C14: 68007.34

Sheet Pivot_Region
A1: Sales & Profit by Region
A3: Row Labels | B3: Sum of Sales | C3: Sum of Profit
A4: East | B4: 94036.48 | C4: 17483.34
A5: North | B5: 113374.47 | C5: 20194.51
A6: South | B6: 85396.84 | C6: 15727.34
A7: West | B7: 81964.01 | C7: 14602.15
A8: Grand Total | B8: 374771.8 | C8: 68007.34

Sheet Pivot_Category
A1: Sales & Profit by Category
A3: Row Labels | B3: Sum of Sales | C3: Sum of Profit
A4: Accessories | B4: 36778.05 | C4: 6695.4
A5: Electronics | B5: 223999.45 | C5: 40998.9
A6: Furniture | B6: 113994.3 | C6: 20313.04
A7: Grand Total | B7: 374771.8 | C7: 68007.34

Sheet Pivot_Monthly
A1: Monthly Sales & Profit
A3: Row Labels | B3: Sum of Sales | C3: Sum of Profit
A4: Jan | B4: 24899.8 | C4: 4501.78
A5: Feb | B5: 30153.03 | C5: 5316.82
A6: Mar | B6: 19529.99 | C6: 4029.56
A7: Apr | B7: 40479.13 | C7: 7218.49
A8: May | B8: 41506.31 | C8: 7871.75
A9: Jun | B9: 39508.09 | C9: 6910.24
A10: Jul | B10: 25939.47 | C10: 5336.61
A11: Aug | B11: 23560.22 | C11: 3876.78
A12: Sep | B12: 34100.97 | C12: 6477
A13: Oct | B13: 20621.77 | C13: 3585.24
A14: Nov | B14: 32746.77 | C14: 5454.66
A15: Dec | B15: 41726.25 | C15: 7428.41
A16: Grand Total | B16: 374771.8 | C16: 68007.34

Sheet Dashboard
A5: KIPs Cards
A6: Total Orders | D6: Total Quantity Sold | G6: Total Sales | J6: Total Profit
A7: 500 | D7: 2274 | G7: 374771.8 | J7: 68007.34
